fn foo(x: Int) {
    try print()
    catch (Exception e) print()
    catch (Exception e) print()
    catch (Exception e) print()
}
